[Tue Feb 27 17:27:50.309673 2018] [mpm_worker:notice] [pid 35694:tid 140249200662400] AH00292: Apache/2.4.29 (Unix) mod_wsgi/4.5.24 Python/3.5 configured -- resuming normal operations
[Tue Feb 27 17:27:50.309791 2018] [core:notice] [pid 35694:tid 140249200662400] AH00094: Command line: '/home/nekoleo/webapps/personalpage/apache2/bin/httpd.worker -f /home/nekoleo/webapps/personalpage/apache2/conf/httpd.conf'
[Tue Feb 27 18:21:04.197021 2018] [wsgi:error] [pid 35696:tid 140249120605952] [remote 127.0.0.1:39014] mod_wsgi (pid=35696): Target WSGI script '/home/nekoleo/webapps/personalpage/htdocs/index.py' cannot be loaded as Python module.
[Tue Feb 27 18:21:04.197091 2018] [wsgi:error] [pid 35696:tid 140249120605952] [remote 127.0.0.1:39014] mod_wsgi (pid=35696): Exception occurred processing WSGI script '/home/nekoleo/webapps/personalpage/htdocs/index.py'.
[Tue Feb 27 18:21:04.198399 2018] [wsgi:error] [pid 35696:tid 140249120605952] [remote 127.0.0.1:39014] Traceback (most recent call last):
[Tue Feb 27 18:21:04.198428 2018] [wsgi:error] [pid 35696:tid 140249120605952] [remote 127.0.0.1:39014]   File "/home/nekoleo/webapps/personalpage/htdocs/index.py", line 14, in <module>
[Tue Feb 27 18:21:04.198433 2018] [wsgi:error] [pid 35696:tid 140249120605952] [remote 127.0.0.1:39014]     from server import app as application
[Tue Feb 27 18:21:04.198449 2018] [wsgi:error] [pid 35696:tid 140249120605952] [remote 127.0.0.1:39014] ImportError: No module named 'server'
[Tue Feb 27 18:21:08.443590 2018] [wsgi:error] [pid 35696:tid 140249028286208] [remote 127.0.0.1:39210] mod_wsgi (pid=35696): Target WSGI script '/home/nekoleo/webapps/personalpage/htdocs/index.py' cannot be loaded as Python module.
[Tue Feb 27 18:21:08.443670 2018] [wsgi:error] [pid 35696:tid 140249028286208] [remote 127.0.0.1:39210] mod_wsgi (pid=35696): Exception occurred processing WSGI script '/home/nekoleo/webapps/personalpage/htdocs/index.py'.
[Tue Feb 27 18:21:08.443805 2018] [wsgi:error] [pid 35696:tid 140249028286208] [remote 127.0.0.1:39210] Traceback (most recent call last):
[Tue Feb 27 18:21:08.443850 2018] [wsgi:error] [pid 35696:tid 140249028286208] [remote 127.0.0.1:39210]   File "/home/nekoleo/webapps/personalpage/htdocs/index.py", line 14, in <module>
[Tue Feb 27 18:21:08.443858 2018] [wsgi:error] [pid 35696:tid 140249028286208] [remote 127.0.0.1:39210]     from server import app as application
[Tue Feb 27 18:21:08.443886 2018] [wsgi:error] [pid 35696:tid 140249028286208] [remote 127.0.0.1:39210] ImportError: No module named 'server'
[Tue Feb 27 18:25:39.379652 2018] [wsgi:error] [pid 35696:tid 140249120605952] [remote 127.0.0.1:51192] mod_wsgi (pid=35696): Target WSGI script '/home/nekoleo/webapps/personalpage/htdocs/index.py' cannot be loaded as Python module.
[Tue Feb 27 18:25:39.379713 2018] [wsgi:error] [pid 35696:tid 140249120605952] [remote 127.0.0.1:51192] mod_wsgi (pid=35696): Exception occurred processing WSGI script '/home/nekoleo/webapps/personalpage/htdocs/index.py'.
[Tue Feb 27 18:25:39.379804 2018] [wsgi:error] [pid 35696:tid 140249120605952] [remote 127.0.0.1:51192] Traceback (most recent call last):
[Tue Feb 27 18:25:39.379829 2018] [wsgi:error] [pid 35696:tid 140249120605952] [remote 127.0.0.1:51192]   File "/home/nekoleo/webapps/personalpage/htdocs/index.py", line 14, in <module>
[Tue Feb 27 18:25:39.379834 2018] [wsgi:error] [pid 35696:tid 140249120605952] [remote 127.0.0.1:51192]     from server import app as application
[Tue Feb 27 18:25:39.379854 2018] [wsgi:error] [pid 35696:tid 140249120605952] [remote 127.0.0.1:51192] ImportError: No module named 'server'
[Tue Feb 27 18:26:21.609858 2018] [wsgi:error] [pid 5657:tid 140249120605952] [remote 127.0.0.1:53124] mod_wsgi (pid=5657): Target WSGI script '/home/nekoleo/webapps/personalpage/htdocs/index.py' cannot be loaded as Python module.
[Tue Feb 27 18:26:21.609912 2018] [wsgi:error] [pid 5657:tid 140249120605952] [remote 127.0.0.1:53124] mod_wsgi (pid=5657): Exception occurred processing WSGI script '/home/nekoleo/webapps/personalpage/htdocs/index.py'.
[Tue Feb 27 18:26:21.610141 2018] [wsgi:error] [pid 5657:tid 140249120605952] [remote 127.0.0.1:53124] Traceback (most recent call last):
[Tue Feb 27 18:26:21.610177 2018] [wsgi:error] [pid 5657:tid 140249120605952] [remote 127.0.0.1:53124]   File "/home/nekoleo/webapps/personalpage/htdocs/index.py", line 14, in <module>
[Tue Feb 27 18:26:21.610181 2018] [wsgi:error] [pid 5657:tid 140249120605952] [remote 127.0.0.1:53124]     from server import app as application
[Tue Feb 27 18:26:21.610197 2018] [wsgi:error] [pid 5657:tid 140249120605952] [remote 127.0.0.1:53124] ImportError: No module named 'server'
[Tue Feb 27 18:27:45.887747 2018] [mpm_worker:notice] [pid 35694:tid 140249200662400] AH00298: SIGHUP received.  Attempting to restart
[Tue Feb 27 18:27:45.941996 2018] [mpm_worker:notice] [pid 35694:tid 140249200662400] AH00292: Apache/2.4.29 (Unix) mod_wsgi/4.5.24 Python/3.5 configured -- resuming normal operations
[Tue Feb 27 18:27:45.942027 2018] [core:notice] [pid 35694:tid 140249200662400] AH00094: Command line: '/home/nekoleo/webapps/personalpage/apache2/bin/httpd.worker -f /home/nekoleo/webapps/personalpage/apache2/conf/httpd.conf'
[Tue Feb 27 18:52:41.738784 2018] [mpm_worker:notice] [pid 35694:tid 140249200662400] AH00298: SIGHUP received.  Attempting to restart
[Tue Feb 27 18:52:41.794707 2018] [mpm_worker:notice] [pid 35694:tid 140249200662400] AH00292: Apache/2.4.29 (Unix) mod_wsgi/4.5.24 Python/3.5 configured -- resuming normal operations
[Tue Feb 27 18:52:41.794734 2018] [core:notice] [pid 35694:tid 140249200662400] AH00094: Command line: '/home/nekoleo/webapps/personalpage/apache2/bin/httpd.worker -f /home/nekoleo/webapps/personalpage/apache2/conf/httpd.conf'
[Tue Feb 27 18:52:45.356923 2018] [wsgi:error] [pid 46665:tid 140249110095616] [remote 127.0.0.1:40926] mod_wsgi (pid=46665): Target WSGI script '/home/nekoleo/webapps/personalpage/htdocs/index.py' cannot be loaded as Python module.
[Tue Feb 27 18:52:45.357001 2018] [wsgi:error] [pid 46665:tid 140249110095616] [remote 127.0.0.1:40926] mod_wsgi (pid=46665): Exception occurred processing WSGI script '/home/nekoleo/webapps/personalpage/htdocs/index.py'.
[Tue Feb 27 18:52:45.357739 2018] [wsgi:error] [pid 46665:tid 140249110095616] [remote 127.0.0.1:40926] Traceback (most recent call last):
[Tue Feb 27 18:52:45.357776 2018] [wsgi:error] [pid 46665:tid 140249110095616] [remote 127.0.0.1:40926]   File "/home/nekoleo/webapps/personalpage/htdocs/index.py", line 14, in <module>
[Tue Feb 27 18:52:45.357781 2018] [wsgi:error] [pid 46665:tid 140249110095616] [remote 127.0.0.1:40926]     from MJFlask import app as application
[Tue Feb 27 18:52:45.357788 2018] [wsgi:error] [pid 46665:tid 140249110095616] [remote 127.0.0.1:40926]   File "/home/nekoleo/webapps/personalpage/src/MJFlask.py", line 9, in <module>
[Tue Feb 27 18:52:45.357791 2018] [wsgi:error] [pid 46665:tid 140249110095616] [remote 127.0.0.1:40926]     from cvutils_dev import *
[Tue Feb 27 18:52:45.357797 2018] [wsgi:error] [pid 46665:tid 140249110095616] [remote 127.0.0.1:40926]   File "/home/nekoleo/webapps/personalpage/src/cvutils_dev.py", line 7, in <module>
[Tue Feb 27 18:52:45.357800 2018] [wsgi:error] [pid 46665:tid 140249110095616] [remote 127.0.0.1:40926]     import numpy as np
[Tue Feb 27 18:52:45.357818 2018] [wsgi:error] [pid 46665:tid 140249110095616] [remote 127.0.0.1:40926] ImportError: No module named 'numpy'
[Tue Feb 27 18:52:46.751339 2018] [wsgi:error] [pid 46666:tid 140249118488320] [remote 127.0.0.1:41018] mod_wsgi (pid=46666): Target WSGI script '/home/nekoleo/webapps/personalpage/htdocs/index.py' cannot be loaded as Python module.
[Tue Feb 27 18:52:46.751412 2018] [wsgi:error] [pid 46666:tid 140249118488320] [remote 127.0.0.1:41018] mod_wsgi (pid=46666): Exception occurred processing WSGI script '/home/nekoleo/webapps/personalpage/htdocs/index.py'.
[Tue Feb 27 18:52:46.751925 2018] [wsgi:error] [pid 46666:tid 140249118488320] [remote 127.0.0.1:41018] Traceback (most recent call last):
[Tue Feb 27 18:52:46.751957 2018] [wsgi:error] [pid 46666:tid 140249118488320] [remote 127.0.0.1:41018]   File "/home/nekoleo/webapps/personalpage/htdocs/index.py", line 14, in <module>
[Tue Feb 27 18:52:46.751975 2018] [wsgi:error] [pid 46666:tid 140249118488320] [remote 127.0.0.1:41018]     from MJFlask import app as application
[Tue Feb 27 18:52:46.751983 2018] [wsgi:error] [pid 46666:tid 140249118488320] [remote 127.0.0.1:41018]   File "/home/nekoleo/webapps/personalpage/src/MJFlask.py", line 9, in <module>
[Tue Feb 27 18:52:46.751986 2018] [wsgi:error] [pid 46666:tid 140249118488320] [remote 127.0.0.1:41018]     from cvutils_dev import *
[Tue Feb 27 18:52:46.751991 2018] [wsgi:error] [pid 46666:tid 140249118488320] [remote 127.0.0.1:41018]   File "/home/nekoleo/webapps/personalpage/src/cvutils_dev.py", line 7, in <module>
[Tue Feb 27 18:52:46.751994 2018] [wsgi:error] [pid 46666:tid 140249118488320] [remote 127.0.0.1:41018]     import numpy as np
[Tue Feb 27 18:52:46.752011 2018] [wsgi:error] [pid 46666:tid 140249118488320] [remote 127.0.0.1:41018] ImportError: No module named 'numpy'
[Tue Feb 27 18:57:47.485382 2018] [wsgi:error] [pid 46665:tid 140248950699776] [remote 127.0.0.1:55978] mod_wsgi (pid=46665): Target WSGI script '/home/nekoleo/webapps/personalpage/htdocs/index.py' cannot be loaded as Python module.
[Tue Feb 27 18:57:47.485460 2018] [wsgi:error] [pid 46665:tid 140248950699776] [remote 127.0.0.1:55978] mod_wsgi (pid=46665): Exception occurred processing WSGI script '/home/nekoleo/webapps/personalpage/htdocs/index.py'.
[Tue Feb 27 18:57:47.486761 2018] [wsgi:error] [pid 46665:tid 140248950699776] [remote 127.0.0.1:55978] Traceback (most recent call last):
[Tue Feb 27 18:57:47.486807 2018] [wsgi:error] [pid 46665:tid 140248950699776] [remote 127.0.0.1:55978]   File "/home/nekoleo/webapps/personalpage/htdocs/index.py", line 14, in <module>
[Tue Feb 27 18:57:47.486812 2018] [wsgi:error] [pid 46665:tid 140248950699776] [remote 127.0.0.1:55978]     from MJFlask import app as application
[Tue Feb 27 18:57:47.486818 2018] [wsgi:error] [pid 46665:tid 140248950699776] [remote 127.0.0.1:55978]   File "/home/nekoleo/webapps/personalpage/src/MJFlask.py", line 16, in <module>
[Tue Feb 27 18:57:47.486821 2018] [wsgi:error] [pid 46665:tid 140248950699776] [remote 127.0.0.1:55978]     SECTIONS_DB=openpyxl.load_workbook(r'data\\Sections.xlsx')
[Tue Feb 27 18:57:47.486827 2018] [wsgi:error] [pid 46665:tid 140248950699776] [remote 127.0.0.1:55978]   File "/home/nekoleo/webapps/personalpage/per-page/lib/python3.5/site-packages/openpyxl/reader/excel.py", line 174, in load_workbook
[Tue Feb 27 18:57:47.486831 2018] [wsgi:error] [pid 46665:tid 140248950699776] [remote 127.0.0.1:55978]     archive = _validate_archive(filename)
[Tue Feb 27 18:57:47.486836 2018] [wsgi:error] [pid 46665:tid 140248950699776] [remote 127.0.0.1:55978]   File "/home/nekoleo/webapps/personalpage/per-page/lib/python3.5/site-packages/openpyxl/reader/excel.py", line 121, in _validate_archive
[Tue Feb 27 18:57:47.486840 2018] [wsgi:error] [pid 46665:tid 140248950699776] [remote 127.0.0.1:55978]     archive = ZipFile(filename, 'r', ZIP_DEFLATED)
[Tue Feb 27 18:57:47.486845 2018] [wsgi:error] [pid 46665:tid 140248950699776] [remote 127.0.0.1:55978]   File "/usr/local/lib/python3.5/zipfile.py", line 1009, in __init__
[Tue Feb 27 18:57:47.486848 2018] [wsgi:error] [pid 46665:tid 140248950699776] [remote 127.0.0.1:55978]     self.fp = io.open(file, filemode)
[Tue Feb 27 18:57:47.486868 2018] [wsgi:error] [pid 46665:tid 140248950699776] [remote 127.0.0.1:55978] FileNotFoundError: [Errno 2] No such file or directory: 'data\\\\Sections.xlsx'
[Tue Feb 27 18:57:48.661649 2018] [wsgi:error] [pid 46666:tid 140249026168576] [remote 127.0.0.1:56030] mod_wsgi (pid=46666): Target WSGI script '/home/nekoleo/webapps/personalpage/htdocs/index.py' cannot be loaded as Python module.
[Tue Feb 27 18:57:48.661716 2018] [wsgi:error] [pid 46666:tid 140249026168576] [remote 127.0.0.1:56030] mod_wsgi (pid=46666): Exception occurred processing WSGI script '/home/nekoleo/webapps/personalpage/htdocs/index.py'.
[Tue Feb 27 18:57:48.662541 2018] [wsgi:error] [pid 46666:tid 140249026168576] [remote 127.0.0.1:56030] Traceback (most recent call last):
[Tue Feb 27 18:57:48.662598 2018] [wsgi:error] [pid 46666:tid 140249026168576] [remote 127.0.0.1:56030]   File "/home/nekoleo/webapps/personalpage/htdocs/index.py", line 14, in <module>
[Tue Feb 27 18:57:48.662603 2018] [wsgi:error] [pid 46666:tid 140249026168576] [remote 127.0.0.1:56030]     from MJFlask import app as application
[Tue Feb 27 18:57:48.662609 2018] [wsgi:error] [pid 46666:tid 140249026168576] [remote 127.0.0.1:56030]   File "/home/nekoleo/webapps/personalpage/src/MJFlask.py", line 16, in <module>
[Tue Feb 27 18:57:48.662612 2018] [wsgi:error] [pid 46666:tid 140249026168576] [remote 127.0.0.1:56030]     SECTIONS_DB=openpyxl.load_workbook(r'data\\Sections.xlsx')
[Tue Feb 27 18:57:48.662618 2018] [wsgi:error] [pid 46666:tid 140249026168576] [remote 127.0.0.1:56030]   File "/home/nekoleo/webapps/personalpage/per-page/lib/python3.5/site-packages/openpyxl/reader/excel.py", line 174, in load_workbook
[Tue Feb 27 18:57:48.662621 2018] [wsgi:error] [pid 46666:tid 140249026168576] [remote 127.0.0.1:56030]     archive = _validate_archive(filename)
[Tue Feb 27 18:57:48.662627 2018] [wsgi:error] [pid 46666:tid 140249026168576] [remote 127.0.0.1:56030]   File "/home/nekoleo/webapps/personalpage/per-page/lib/python3.5/site-packages/openpyxl/reader/excel.py", line 121, in _validate_archive
[Tue Feb 27 18:57:48.662630 2018] [wsgi:error] [pid 46666:tid 140249026168576] [remote 127.0.0.1:56030]     archive = ZipFile(filename, 'r', ZIP_DEFLATED)
[Tue Feb 27 18:57:48.662635 2018] [wsgi:error] [pid 46666:tid 140249026168576] [remote 127.0.0.1:56030]   File "/usr/local/lib/python3.5/zipfile.py", line 1009, in __init__
[Tue Feb 27 18:57:48.662638 2018] [wsgi:error] [pid 46666:tid 140249026168576] [remote 127.0.0.1:56030]     self.fp = io.open(file, filemode)
[Tue Feb 27 18:57:48.662654 2018] [wsgi:error] [pid 46666:tid 140249026168576] [remote 127.0.0.1:56030] FileNotFoundError: [Errno 2] No such file or directory: 'data\\\\Sections.xlsx'
[Tue Feb 27 19:01:20.852377 2018] [wsgi:error] [pid 46665:tid 140249110095616] [remote 127.0.0.1:36798] mod_wsgi (pid=46665): Target WSGI script '/home/nekoleo/webapps/personalpage/htdocs/index.py' cannot be loaded as Python module.
[Tue Feb 27 19:01:20.852483 2018] [wsgi:error] [pid 46665:tid 140249110095616] [remote 127.0.0.1:36798] mod_wsgi (pid=46665): Exception occurred processing WSGI script '/home/nekoleo/webapps/personalpage/htdocs/index.py'.
[Tue Feb 27 19:01:20.852705 2018] [wsgi:error] [pid 46665:tid 140249110095616] [remote 127.0.0.1:36798] Traceback (most recent call last):
[Tue Feb 27 19:01:20.852776 2018] [wsgi:error] [pid 46665:tid 140249110095616] [remote 127.0.0.1:36798]   File "/home/nekoleo/webapps/personalpage/htdocs/index.py", line 14, in <module>
[Tue Feb 27 19:01:20.852784 2018] [wsgi:error] [pid 46665:tid 140249110095616] [remote 127.0.0.1:36798]     from MJFlask import app as application
[Tue Feb 27 19:01:20.852795 2018] [wsgi:error] [pid 46665:tid 140249110095616] [remote 127.0.0.1:36798]   File "/home/nekoleo/webapps/personalpage/src/MJFlask.py", line 16, in <module>
[Tue Feb 27 19:01:20.852800 2018] [wsgi:error] [pid 46665:tid 140249110095616] [remote 127.0.0.1:36798]     SECTIONS_DB=openpyxl.load_workbook(r'data\\Sections.xlsx')
[Tue Feb 27 19:01:20.852813 2018] [wsgi:error] [pid 46665:tid 140249110095616] [remote 127.0.0.1:36798]   File "/home/nekoleo/webapps/personalpage/per-page/lib/python3.5/site-packages/openpyxl/reader/excel.py", line 174, in load_workbook
[Tue Feb 27 19:01:20.852819 2018] [wsgi:error] [pid 46665:tid 140249110095616] [remote 127.0.0.1:36798]     archive = _validate_archive(filename)
[Tue Feb 27 19:01:20.852829 2018] [wsgi:error] [pid 46665:tid 140249110095616] [remote 127.0.0.1:36798]   File "/home/nekoleo/webapps/personalpage/per-page/lib/python3.5/site-packages/openpyxl/reader/excel.py", line 121, in _validate_archive
[Tue Feb 27 19:01:20.852835 2018] [wsgi:error] [pid 46665:tid 140249110095616] [remote 127.0.0.1:36798]     archive = ZipFile(filename, 'r', ZIP_DEFLATED)
[Tue Feb 27 19:01:20.852845 2018] [wsgi:error] [pid 46665:tid 140249110095616] [remote 127.0.0.1:36798]   File "/usr/local/lib/python3.5/zipfile.py", line 1009, in __init__
[Tue Feb 27 19:01:20.852864 2018] [wsgi:error] [pid 46665:tid 140249110095616] [remote 127.0.0.1:36798]     self.fp = io.open(file, filemode)
[Tue Feb 27 19:01:20.852892 2018] [wsgi:error] [pid 46665:tid 140249110095616] [remote 127.0.0.1:36798] FileNotFoundError: [Errno 2] No such file or directory: 'data\\\\Sections.xlsx'
[Tue Feb 27 19:01:21.811619 2018] [wsgi:error] [pid 46666:tid 140249118488320] [remote 127.0.0.1:36876] mod_wsgi (pid=46666): Target WSGI script '/home/nekoleo/webapps/personalpage/htdocs/index.py' cannot be loaded as Python module.
[Tue Feb 27 19:01:21.811707 2018] [wsgi:error] [pid 46666:tid 140249118488320] [remote 127.0.0.1:36876] mod_wsgi (pid=46666): Exception occurred processing WSGI script '/home/nekoleo/webapps/personalpage/htdocs/index.py'.
[Tue Feb 27 19:01:21.811919 2018] [wsgi:error] [pid 46666:tid 140249118488320] [remote 127.0.0.1:36876] Traceback (most recent call last):
[Tue Feb 27 19:01:21.811980 2018] [wsgi:error] [pid 46666:tid 140249118488320] [remote 127.0.0.1:36876]   File "/home/nekoleo/webapps/personalpage/htdocs/index.py", line 14, in <module>
[Tue Feb 27 19:01:21.811987 2018] [wsgi:error] [pid 46666:tid 140249118488320] [remote 127.0.0.1:36876]     from MJFlask import app as application
[Tue Feb 27 19:01:21.811998 2018] [wsgi:error] [pid 46666:tid 140249118488320] [remote 127.0.0.1:36876]   File "/home/nekoleo/webapps/personalpage/src/MJFlask.py", line 16, in <module>
[Tue Feb 27 19:01:21.812003 2018] [wsgi:error] [pid 46666:tid 140249118488320] [remote 127.0.0.1:36876]     SECTIONS_DB=openpyxl.load_workbook(r'data\\Sections.xlsx')
[Tue Feb 27 19:01:21.812014 2018] [wsgi:error] [pid 46666:tid 140249118488320] [remote 127.0.0.1:36876]   File "/home/nekoleo/webapps/personalpage/per-page/lib/python3.5/site-packages/openpyxl/reader/excel.py", line 174, in load_workbook
[Tue Feb 27 19:01:21.812020 2018] [wsgi:error] [pid 46666:tid 140249118488320] [remote 127.0.0.1:36876]     archive = _validate_archive(filename)
[Tue Feb 27 19:01:21.812030 2018] [wsgi:error] [pid 46666:tid 140249118488320] [remote 127.0.0.1:36876]   File "/home/nekoleo/webapps/personalpage/per-page/lib/python3.5/site-packages/openpyxl/reader/excel.py", line 121, in _validate_archive
[Tue Feb 27 19:01:21.812036 2018] [wsgi:error] [pid 46666:tid 140249118488320] [remote 127.0.0.1:36876]     archive = ZipFile(filename, 'r', ZIP_DEFLATED)
[Tue Feb 27 19:01:21.812046 2018] [wsgi:error] [pid 46666:tid 140249118488320] [remote 127.0.0.1:36876]   File "/usr/local/lib/python3.5/zipfile.py", line 1009, in __init__
[Tue Feb 27 19:01:21.812051 2018] [wsgi:error] [pid 46666:tid 140249118488320] [remote 127.0.0.1:36876]     self.fp = io.open(file, filemode)
[Tue Feb 27 19:01:21.812077 2018] [wsgi:error] [pid 46666:tid 140249118488320] [remote 127.0.0.1:36876] FileNotFoundError: [Errno 2] No such file or directory: 'data\\\\Sections.xlsx'
[Tue Feb 27 19:02:57.836336 2018] [wsgi:error] [pid 46665:tid 140248950699776] [remote 127.0.0.1:42120] mod_wsgi (pid=46665): Target WSGI script '/home/nekoleo/webapps/personalpage/htdocs/index.py' cannot be loaded as Python module.
[Tue Feb 27 19:02:57.836421 2018] [wsgi:error] [pid 46665:tid 140248950699776] [remote 127.0.0.1:42120] mod_wsgi (pid=46665): Exception occurred processing WSGI script '/home/nekoleo/webapps/personalpage/htdocs/index.py'.
[Tue Feb 27 19:02:57.836946 2018] [wsgi:error] [pid 46665:tid 140248950699776] [remote 127.0.0.1:42120] Traceback (most recent call last):
[Tue Feb 27 19:02:57.837010 2018] [wsgi:error] [pid 46665:tid 140248950699776] [remote 127.0.0.1:42120]   File "/home/nekoleo/webapps/personalpage/htdocs/index.py", line 14, in <module>
[Tue Feb 27 19:02:57.837018 2018] [wsgi:error] [pid 46665:tid 140248950699776] [remote 127.0.0.1:42120]     from MJFlask import app as application
[Tue Feb 27 19:02:57.837029 2018] [wsgi:error] [pid 46665:tid 140248950699776] [remote 127.0.0.1:42120]   File "/home/nekoleo/webapps/personalpage/src/MJFlask.py", line 16, in <module>
[Tue Feb 27 19:02:57.837046 2018] [wsgi:error] [pid 46665:tid 140248950699776] [remote 127.0.0.1:42120]     SECTIONS_DB=openpyxl.load_workbook(r'data/Sections.xlsx')
[Tue Feb 27 19:02:57.837057 2018] [wsgi:error] [pid 46665:tid 140248950699776] [remote 127.0.0.1:42120]   File "/home/nekoleo/webapps/personalpage/per-page/lib/python3.5/site-packages/openpyxl/reader/excel.py", line 174, in load_workbook
[Tue Feb 27 19:02:57.837063 2018] [wsgi:error] [pid 46665:tid 140248950699776] [remote 127.0.0.1:42120]     archive = _validate_archive(filename)
[Tue Feb 27 19:02:57.837072 2018] [wsgi:error] [pid 46665:tid 140248950699776] [remote 127.0.0.1:42120]   File "/home/nekoleo/webapps/personalpage/per-page/lib/python3.5/site-packages/openpyxl/reader/excel.py", line 121, in _validate_archive
[Tue Feb 27 19:02:57.837078 2018] [wsgi:error] [pid 46665:tid 140248950699776] [remote 127.0.0.1:42120]     archive = ZipFile(filename, 'r', ZIP_DEFLATED)
[Tue Feb 27 19:02:57.837088 2018] [wsgi:error] [pid 46665:tid 140248950699776] [remote 127.0.0.1:42120]   File "/usr/local/lib/python3.5/zipfile.py", line 1009, in __init__
[Tue Feb 27 19:02:57.837092 2018] [wsgi:error] [pid 46665:tid 140248950699776] [remote 127.0.0.1:42120]     self.fp = io.open(file, filemode)
[Tue Feb 27 19:02:57.837120 2018] [wsgi:error] [pid 46665:tid 140248950699776] [remote 127.0.0.1:42120] FileNotFoundError: [Errno 2] No such file or directory: 'data/Sections.xlsx'
[Tue Feb 27 19:02:58.771123 2018] [wsgi:error] [pid 46666:tid 140249026168576] [remote 127.0.0.1:42136] mod_wsgi (pid=46666): Target WSGI script '/home/nekoleo/webapps/personalpage/htdocs/index.py' cannot be loaded as Python module.
[Tue Feb 27 19:02:58.771196 2018] [wsgi:error] [pid 46666:tid 140249026168576] [remote 127.0.0.1:42136] mod_wsgi (pid=46666): Exception occurred processing WSGI script '/home/nekoleo/webapps/personalpage/htdocs/index.py'.
[Tue Feb 27 19:02:58.771889 2018] [wsgi:error] [pid 46666:tid 140249026168576] [remote 127.0.0.1:42136] Traceback (most recent call last):
[Tue Feb 27 19:02:58.771957 2018] [wsgi:error] [pid 46666:tid 140249026168576] [remote 127.0.0.1:42136]   File "/home/nekoleo/webapps/personalpage/htdocs/index.py", line 14, in <module>
[Tue Feb 27 19:02:58.771965 2018] [wsgi:error] [pid 46666:tid 140249026168576] [remote 127.0.0.1:42136]     from MJFlask import app as application
[Tue Feb 27 19:02:58.771975 2018] [wsgi:error] [pid 46666:tid 140249026168576] [remote 127.0.0.1:42136]   File "/home/nekoleo/webapps/personalpage/src/MJFlask.py", line 16, in <module>
[Tue Feb 27 19:02:58.771981 2018] [wsgi:error] [pid 46666:tid 140249026168576] [remote 127.0.0.1:42136]     SECTIONS_DB=openpyxl.load_workbook(r'data/Sections.xlsx')
[Tue Feb 27 19:02:58.771991 2018] [wsgi:error] [pid 46666:tid 140249026168576] [remote 127.0.0.1:42136]   File "/home/nekoleo/webapps/personalpage/per-page/lib/python3.5/site-packages/openpyxl/reader/excel.py", line 174, in load_workbook
[Tue Feb 27 19:02:58.771997 2018] [wsgi:error] [pid 46666:tid 140249026168576] [remote 127.0.0.1:42136]     archive = _validate_archive(filename)
[Tue Feb 27 19:02:58.772006 2018] [wsgi:error] [pid 46666:tid 140249026168576] [remote 127.0.0.1:42136]   File "/home/nekoleo/webapps/personalpage/per-page/lib/python3.5/site-packages/openpyxl/reader/excel.py", line 121, in _validate_archive
[Tue Feb 27 19:02:58.772012 2018] [wsgi:error] [pid 46666:tid 140249026168576] [remote 127.0.0.1:42136]     archive = ZipFile(filename, 'r', ZIP_DEFLATED)
[Tue Feb 27 19:02:58.772021 2018] [wsgi:error] [pid 46666:tid 140249026168576] [remote 127.0.0.1:42136]   File "/usr/local/lib/python3.5/zipfile.py", line 1009, in __init__
[Tue Feb 27 19:02:58.772026 2018] [wsgi:error] [pid 46666:tid 140249026168576] [remote 127.0.0.1:42136]     self.fp = io.open(file, filemode)
[Tue Feb 27 19:02:58.772053 2018] [wsgi:error] [pid 46666:tid 140249026168576] [remote 127.0.0.1:42136] FileNotFoundError: [Errno 2] No such file or directory: 'data/Sections.xlsx'
[Tue Feb 27 19:03:02.903424 2018] [wsgi:error] [pid 46665:tid 140249110095616] [remote 127.0.0.1:42266] mod_wsgi (pid=46665): Target WSGI script '/home/nekoleo/webapps/personalpage/htdocs/index.py' cannot be loaded as Python module.
[Tue Feb 27 19:03:02.903550 2018] [wsgi:error] [pid 46665:tid 140249110095616] [remote 127.0.0.1:42266] mod_wsgi (pid=46665): Exception occurred processing WSGI script '/home/nekoleo/webapps/personalpage/htdocs/index.py'.
[Tue Feb 27 19:03:02.903793 2018] [wsgi:error] [pid 46665:tid 140249110095616] [remote 127.0.0.1:42266] Traceback (most recent call last):
[Tue Feb 27 19:03:02.903861 2018] [wsgi:error] [pid 46665:tid 140249110095616] [remote 127.0.0.1:42266]   File "/home/nekoleo/webapps/personalpage/htdocs/index.py", line 14, in <module>
[Tue Feb 27 19:03:02.903869 2018] [wsgi:error] [pid 46665:tid 140249110095616] [remote 127.0.0.1:42266]     from MJFlask import app as application
[Tue Feb 27 19:03:02.903880 2018] [wsgi:error] [pid 46665:tid 140249110095616] [remote 127.0.0.1:42266]   File "/home/nekoleo/webapps/personalpage/src/MJFlask.py", line 16, in <module>
[Tue Feb 27 19:03:02.903886 2018] [wsgi:error] [pid 46665:tid 140249110095616] [remote 127.0.0.1:42266]     SECTIONS_DB=openpyxl.load_workbook(r'data/Sections.xlsx')
[Tue Feb 27 19:03:02.903912 2018] [wsgi:error] [pid 46665:tid 140249110095616] [remote 127.0.0.1:42266]   File "/home/nekoleo/webapps/personalpage/per-page/lib/python3.5/site-packages/openpyxl/reader/excel.py", line 174, in load_workbook
[Tue Feb 27 19:03:02.903919 2018] [wsgi:error] [pid 46665:tid 140249110095616] [remote 127.0.0.1:42266]     archive = _validate_archive(filename)
[Tue Feb 27 19:03:02.903930 2018] [wsgi:error] [pid 46665:tid 140249110095616] [remote 127.0.0.1:42266]   File "/home/nekoleo/webapps/personalpage/per-page/lib/python3.5/site-packages/openpyxl/reader/excel.py", line 121, in _validate_archive
[Tue Feb 27 19:03:02.903937 2018] [wsgi:error] [pid 46665:tid 140249110095616] [remote 127.0.0.1:42266]     archive = ZipFile(filename, 'r', ZIP_DEFLATED)
[Tue Feb 27 19:03:02.903947 2018] [wsgi:error] [pid 46665:tid 140249110095616] [remote 127.0.0.1:42266]   File "/usr/local/lib/python3.5/zipfile.py", line 1009, in __init__
[Tue Feb 27 19:03:02.903952 2018] [wsgi:error] [pid 46665:tid 140249110095616] [remote 127.0.0.1:42266]     self.fp = io.open(file, filemode)
[Tue Feb 27 19:03:02.903982 2018] [wsgi:error] [pid 46665:tid 140249110095616] [remote 127.0.0.1:42266] FileNotFoundError: [Errno 2] No such file or directory: 'data/Sections.xlsx'
[Tue Feb 27 19:03:03.432295 2018] [wsgi:error] [pid 46666:tid 140249118488320] [remote 127.0.0.1:42276] mod_wsgi (pid=46666): Target WSGI script '/home/nekoleo/webapps/personalpage/htdocs/index.py' cannot be loaded as Python module.
[Tue Feb 27 19:03:03.432374 2018] [wsgi:error] [pid 46666:tid 140249118488320] [remote 127.0.0.1:42276] mod_wsgi (pid=46666): Exception occurred processing WSGI script '/home/nekoleo/webapps/personalpage/htdocs/index.py'.
[Tue Feb 27 19:03:03.432556 2018] [wsgi:error] [pid 46666:tid 140249118488320] [remote 127.0.0.1:42276] Traceback (most recent call last):
[Tue Feb 27 19:03:03.432607 2018] [wsgi:error] [pid 46666:tid 140249118488320] [remote 127.0.0.1:42276]   File "/home/nekoleo/webapps/personalpage/htdocs/index.py", line 14, in <module>
[Tue Feb 27 19:03:03.432613 2018] [wsgi:error] [pid 46666:tid 140249118488320] [remote 127.0.0.1:42276]     from MJFlask import app as application
[Tue Feb 27 19:03:03.432622 2018] [wsgi:error] [pid 46666:tid 140249118488320] [remote 127.0.0.1:42276]   File "/home/nekoleo/webapps/personalpage/src/MJFlask.py", line 16, in <module>
[Tue Feb 27 19:03:03.432626 2018] [wsgi:error] [pid 46666:tid 140249118488320] [remote 127.0.0.1:42276]     SECTIONS_DB=openpyxl.load_workbook(r'data/Sections.xlsx')
[Tue Feb 27 19:03:03.432634 2018] [wsgi:error] [pid 46666:tid 140249118488320] [remote 127.0.0.1:42276]   File "/home/nekoleo/webapps/personalpage/per-page/lib/python3.5/site-packages/openpyxl/reader/excel.py", line 174, in load_workbook
[Tue Feb 27 19:03:03.432639 2018] [wsgi:error] [pid 46666:tid 140249118488320] [remote 127.0.0.1:42276]     archive = _validate_archive(filename)
[Tue Feb 27 19:03:03.432658 2018] [wsgi:error] [pid 46666:tid 140249118488320] [remote 127.0.0.1:42276]   File "/home/nekoleo/webapps/personalpage/per-page/lib/python3.5/site-packages/openpyxl/reader/excel.py", line 121, in _validate_archive
[Tue Feb 27 19:03:03.432663 2018] [wsgi:error] [pid 46666:tid 140249118488320] [remote 127.0.0.1:42276]     archive = ZipFile(filename, 'r', ZIP_DEFLATED)
[Tue Feb 27 19:03:03.432671 2018] [wsgi:error] [pid 46666:tid 140249118488320] [remote 127.0.0.1:42276]   File "/usr/local/lib/python3.5/zipfile.py", line 1009, in __init__
[Tue Feb 27 19:03:03.432674 2018] [wsgi:error] [pid 46666:tid 140249118488320] [remote 127.0.0.1:42276]     self.fp = io.open(file, filemode)
[Tue Feb 27 19:03:03.432697 2018] [wsgi:error] [pid 46666:tid 140249118488320] [remote 127.0.0.1:42276] FileNotFoundError: [Errno 2] No such file or directory: 'data/Sections.xlsx'
